Workbook

Sheet catalog
B1: Nombre | C1: Categoría | D1: Descripción | E1: Precio | F1: URL de Imagen
A2: 1 | B2: Nuez Mariposa Extra Light x 1 Kg | C2: Frutos Secos | D2: Detallar con palabras claras | E2: 20500 | F2: https://cdn.newgarden.com.ar/media/catalog/product/cache/dda7253a1a2f6711745de410175d10f8/n/u/nuez-pelada-cuartillo-extra-light_1_2_1_1.jpg
A3: =A2+1 -> 2 | B3: Almendra Non Pareil 27/30 x 1 Kg | C3: Frutos Secos | D3: Detallar con palabras claras | E3: 23000 | F3: https://encrypted-tbn0.gstatic.com/images?q=tbn:ANd9GcTnYmm3nBskRSQNDC7mbDaylPr-fLeZ5s2BHQ&s
A4: =A3+1 -> 3 | B4: Mani tostado con y sin sal PREMIUM x 1 Kg | C4: Frutos Secos | D4: Detallar con palabras claras | E4: 3000 | F4: https://cdn.newgarden.com.ar/media/catalog/product/cache/dda7253a1a2f6711745de410175d10f8/1/3/13089-mani-repelado-salado-y-tostado_1.jpg
A5: 4 | B5: Nuez Pecan x 1 Kg | C5: Frutos Secos | D5: Detallar con palabras claras | E5: 34600 | F5: https://cdn.shopify.com/s/files/1/1699/9375/files/la-nuez-pecan-ayuda-a-adelgazar_large.jpg?v=1499651301
A6: =A5+1 -> 5 | B6: Cajú W4 brasilero x 1 Kg | C6: Frutos Secos | D6: Detallar con palabras claras | E6: 19500 | F6: https://dcdn-us.mitiendanube.com/stores/001/569/510/products/_68y17isb6-fe1989881887e9785716430667084431-1024-1024.webp
A7: 6 | B7: Caju Tostadas con sal y sin sal 1kg | C7: Frutos Secos | E7: 20000 | F7: https://ketoandco.com.ar/wp-content/uploads/2024/08/castanas-de-caju-tostadas-y-saladas-2.png
A8: 7 | B8: Castañas de PARA x 1 Kg | C8: Frutos Secos | D8: Detallar con palabras claras | E8: 40200 | F8: https://cdn.newgarden.com.ar/media/catalog/product/cache/dda7253a1a2f6711745de410175d10f8/c/a/castanas-de-para-1-kg.jpg
A9: =A8+1 -> 8 | B9: Avellanas grandes x 1 Kg | C9: Frutos Secos | D9: Detallar con palabras claras | E9: 33200 | F9: https://tse2.mm.bing.net/th/id/OIP.EUdZVDmCv6FQwUlFKj3oMgHaE7?pid=Api&P=0&h=180
A10: 9 | B10: Pasas Rubia 1kg | C10: Frutos Secos | E10: 8200 | F10: https://cdn.newgarden.com.ar/media/catalog/product/cache/dda7253a1a2f6711745de410175d10f8/p/a/pasas-de-uva-rubias-premium-x-1kg.jpg
A11: =A10+1 -> 10 | B11: Pistacho salado con cascara x 1 Kg | C11: Frutos Secos | D11: Detallar con palabras claras | E11: 41000 | F11: https://cdn.newgarden.com.ar/media/catalog/product/cache/dda7253a1a2f6711745de410175d10f8/p/i/pistacho-con-cascara-salado-y-tostado-1kg.jpg
A12: 11 | B12: Maiz Frito salado x 1kg | C12: Frutos Secos | E12: 12000 | F12: https://tse3.mm.bing.net/th/id/OIP.w6yQYT_irw2zFRcafVuuFQAAAA?pid=Api&P=0&h=180
A13: =A11+1 -> 11 | B13: Mix criollo o Runner (Nuez cuartos , almendra, cajú, mani, pasas rubias y morochas) x 1kg | C13: Mix de Frutos secos | E13: 8200 | F13: https://encrypted-tbn0.gstatic.com/images?q=tbn:ANd9GcSKpfMEboVqmOHd2ilCkB_E-_hlK6NGs4wdZg&s
A14: 12 | B14: Mix criollo o Runner SIN MANI (Almendra, nuez, pasas rubias, pasas morochas y caju) 1kg | C14: Mix de Frutos secos | E14: 11700 | F14: https://acdn-us.mitiendanube.com/stores/001/229/173/products/mix-de-frutos-secos-con-pasas-12-kg-d_nq_np_589905-mla25107800259_102016-f1-799a1be3d88edbecbb15945260039537-480-0.jpg
A15: 13 | B15: Mix premium gourmet (Cajú, almendras, nueces y avellanas) x 1kg | C15: Mix de Frutos secos | E15: 23000 | F15: https://acdn-us.mitiendanube.com/stores/001/184/135/products/11-30087acda95d00a49316263074834401-640-0.webp
A16: 14 | B16: Mix europeo (Almendra, nuez, mani y caju) 1kg | C16: Mix de Frutos secos | E16: 12000 | F16: https://acdn-us.mitiendanube.com/stores/001/040/363/products/s-botanica-protectos-solar-fps-30-125ml-611-6b43b3b9208898d57c16717359401681-640-0.png
A17: 15 | B17: Mix criollo o runner con bananitas (Cajú, almendras, nueces, mani, pasas rubias y morochas, bananitas) | C17: Mix de Frutos secos | E17: 8400 | F17: https://http2.mlstatic.com/D_NQ_NP_600579-MLA53014366217_122022-O.webp
A18: =A17+1 -> 16 | B18: Mix cervecero (semillas peladas de girasol y de zapallo, castañas de cajú saladas, maní salado, maní japonés) 1kg | C18: Mix de Frutos secos | E18: 6300 | F18: https://d22fxaf9t8d39k.cloudfront.net/1383ba2a1c02bff5e680d91b32794476f4a03c7f91c4bd15de989ce8bb01e8e565493.png
A19: 17 | B19: Mix Berry ( Arándanos, cerezas, frutillas, nueces, cajú, almendras, coco en escamas y pasas) 1Kg | C19: Mix Frutos secos | E19: 17500 | F19: https://d22fxaf9t8d39k.cloudfront.net/66157a64ab633490eb331455e87ec03e4ce8cac0788ecf398aee49548d7548f465493.jpeg
A20: 18 | B20: Mix Pan Dulce | C20: Mix Frutos secos | E20: 11400 | F20: https://tse3.mm.bing.net/th/id/OIP.ekOVbwPBYW8BCYqov8csBgHaFj?pid=Api&P=0&h=180
A21: 18 | B21: Bananas disecadas x 1kg | C21: Frutas Disecadas | E21: 12000 | F21: https://tse2.mm.bing.net/th/id/OIP.WztaZHMqZeBta6F1Qf1uLwHaHa?pid=Api&P=0&h=180
A22: =A21+1 -> 19 | B22: Damasco turco grande x 1kg | C22: Frutas Disecadas | E22: 42000 | F22: https://cdn.newgarden.com.ar/media/catalog/product/cache/dda7253a1a2f6711745de410175d10f8/d/a/damascos-turcos-gigantes.jpg
A23: =A22+1 -> 20 | B23: Tomates deshidratados x 1kg | C23: Frutas Disecadas | E23: 15600 | F23: https://www.oestepizzaparty.com.ar/wp-content/uploads/2024/07/TOMATE-SECO.jpg
A24: 21 | B24: Peras x 1kg | C24: Frutas Disecadas | E24: 12500 | F24: https://tse3.mm.bing.net/th/id/OIP.zF-rlypNt8a3Ez0oYfijEAHaHa?pid=Api&P=0&h=180
A25: 22 | B25: Durazno Extra Grandes x 1kg | C25: Frutas Disecadas | E25: 18000 | F25: https://frutaslosnogales.com.ar/wp-content/uploads/2017/10/damascos-desecados.jpg
A26: 23 | B26: Ciruelas d Agen sin carozo x 1kg | C26: Frutas Disecadas | E26: 7500 | F26: https://http2.mlstatic.com/D_NQ_NP_817799-MLA49745917640_042022-O.webp
A27: =A26+1 -> 24 | B27: Arandanos | C27: Frutas Disecadas | E27: 13500 | F27: https://http2.mlstatic.com/D_NQ_NP_971630-MLA43638879754_092020-O.webp
A28: =A27+1 -> 25 | B28: Higos negros x 5kg | C28: Frutas Disecadas | E28: 47000 | F28: https://encrypted-tbn0.gstatic.com/images?q=tbn:ANd9GcS8dLvMpss83GZFYyFV7I6LpVznhQOKnMXEzQ&s
A29: =A28+1 -> 26 | B29: Datiles Egipto Caja 1 kg OFERTA | C29: Frutas Disecadas | E29: 8000 | F29: https://http2.mlstatic.com/D_NQ_NP_708601-MLA78585683115_082024-O.webp
B30: datiles Argelia | C30: frutas Disecadas | E30: 11000
A31: =A29+1 -> 27 | B31: Mix de semillas (Lino, girasol, sésamo) x 1kg | C31: Semillas Premium | E31: 4000 | F31: https://encrypted-tbn0.gstatic.com/images?q=tbn:ANd9GcTglzHWASxwluXIIkarYSwqpvnGgcZeuCAcLg&s
A32: =A31+1 -> 28 | B32: Lino x 1Kg | C32: Semillas Premium | E32: 3300 | F32: https://acdn-us.mitiendanube.com/stores/002/625/145/products/granola-exotica-2023-04-03t151215-6301-3106e1387bb613118416805456176298-1024-1024.jpg
A33: =A32+1 -> 29 | B33: Chia premium x 1Kg | C33: Semillas Premium | E33: 8700 | F33: https://http2.mlstatic.com/D_NQ_NP_894603-MLA43239351703_082020-O.webp
A34: =A33+1 -> 30 | B34: Sésamo integral x 1Kg | C34: Semillas Premium | E34: 5800 | F34: https://acdn-us.mitiendanube.com/stores/139/211/products/si1-5f39e3dbf951b2058416613695784776-640-0.jpg
A35: =A34+1 -> 31 | B35: Sesamo blanco x 1Kg | C35: Semillas Premium | E35: 10000 | F35: https://encrypted-tbn0.gstatic.com/images?q=tbn:ANd9GcQntFNQLSfcCRPYfdDWENnN-nnjkiXEd5X_rg&s
A36: =A35+1 -> 32 | B36: Girasol x 1Kg | C36: Semillas Premium | E36: 4100 | F36: https://cdn.newgarden.com.ar/media/catalog/product/cache/dda7253a1a2f6711745de410175d10f8/s/e/semillas-de-girasol.jpg
A37: =A36+1 -> 33 | B37: Quinoa x 1Kg | C37: Semillas Premium | E37: 12400 | F37: https://encrypted-tbn0.gstatic.com/images?q=tbn:ANd9GcSG1kARLaOIE7pGoafKjoedBbAX8hILHyNDMA&s
A38: =A37+1 -> 34 | B38: Zapallo x 1Kg | C38: Semillas Premium | E38: 14000 | F38: https://encrypted-tbn0.gstatic.com/images?q=tbn:ANd9GcTPwa8YpJ2Ttnds1LqAjpNrlaMFFdLbLeE9nw&s
B39: Arroz Yamani- OFERTA- | C39: Arroz | E39: 3500 | F39: https://tse1.mm.bing.net/th/id/OIP.T_wgPNv93guoZVlYExjQhwAAAA?pid=Api&P=0&h=180
A40: =A38+1 -> 35 | F40: https://cdn.newgarden.com.ar/media/catalog/product/cache/dda7253a1a2f6711745de410175d10f8/h/a/harina-de-avena-x-1-kg.jpg
...

Sheet ref
A1: https://newgarden.com.ar/

Sheet pedido distribuidora
A2: 1 | B2: Mix Premiun gourmet | C2: 6 kg | D2: 15500 | E2: =D2*6 -> 93000
A3: 3 | B3: Quinoa | C3: 1kg | D3: 6000 | E3: =D3 -> 6000
A4: 4 | B4: Mani Tostado sin sal | C4: 1kg | D4: 2500 | E4: =D4 -> 2500
A5: 2 | B5: Mix Criollo o runner con banan | C5: 2kg | D5: 6600 | E5: =D5*2 -> 13200
A6: 6 | B6: Harina de Almendras sin piel | C6: 2kg | D6: 3600 | E6: =D6*2 -> 7200
A7: 18 | B7: Mermelada Los Carolinos Durazno | C7: 1 | D7: 2220 | E7: =D7 -> 2220
A8: 8 | B8: Nuez Mariposa | C8: 1kg | D8: 17900 | E8: =D8 -> 17900
A9: 5 | B9: Mani Tostado con sal | C9: 3kg | D9: 2500 | E9: =D9*3 -> 7500
A10: 9 | B10: Pistachos con cascara | C10: 2kg | D10: 28500 | E10: =D10*2 -> 57000
A11: 7 | B11: Harina de Almendras con piel | C11: 2kg | D11: 3400 | E11: =D11*2 -> 6800
A12: 10 | B12: Bananas disecadas | C12: 1kg | D12: 6400 | E12: =D12 -> 6400
A13: 11 | B13: Harina de coco | C13: 2kg | D13: 4600 | E13: =D13*2 -> 9200
A14: 12 | B14: Aceite de coco neutro x 360 | C14: 1 | D14: 3300 | E14: =D14 -> 3300
A15: 13 | B15: Chip chocolate | C15: 1kg | D15: 6600 | E15: =D15 -> 6600
A16: 14 | B16: Galletitas Nutresan sabor coco | C16: 1 | D16: 1130 | E16: =D16 -> 1130
A17: 15 | B17: Galletitas Nutresan sabor algarroba | C17: 1 | D17: 1140 | E17: =D17 -> 1140
B18: castañas caju | C18: 1kg | D18: 12300 | E18: =D18 -> 12300
B19: arandanos | C19: 4kg | D19: 7900 | E19: =D19*4 -> 31600
A20: 16 | B20: mix semillas | C20: 1kg | D20: 2600 | E20: =D20 -> 2600
B21: pasas con chocolate | C21: 1kg | D21: 11000 | E21: =D21 -> 11000
A22: 17 | B22: castañas para | C22: 1kg | D22: 16800 | E22: =D22 -> 16800
A23: 19 | B23: nueces pecan | C23: 1kg | D23: 17100 | E23: =1 -> 1
E24: =SUM(E2:E23) -> 315391

Sheet Clientes
A1: id | B1: cliente
A2: 1 | B2: Cecilia (Lauti)
A3: =A2+1 -> 2 | B3: Marianela (Laure)
A4: =A3+1 -> 3 | B4: Marcela Rivera
A5: =A4+1 -> 4 | B5: Rosario
A6: =A5+1 -> 5 | B6: Saha
A7: =A6+1 -> 6 | B7: Raul
A8: =A7+1 -> 7 | B8: Gustavo
A9: =A8+1 -> 8 | B9: Gabi
A10: =A9+1 -> 9 | B10: Luciano
A11: =A10+1 -> 10 | B11: Auri
A12: =A11+1 -> 11 | B12: Maiju
A13: =A12+1 -> 12 | B13: Luz
A14: =A13+1 -> 13 | B14: Gla
... A37: =A36+1 -> 36 | B37: Marina Moriconi
A38: 37 | B38: Laura Area 10
A39: 38 | B39: Dora area 2
A40: 39 | B40: Juan pablo (vallese)
A41: 40 | B41: Pao Migliaro
A42: 41 | B42: Gisella area 13
A43: 42 | B43: Candela
A44: 43 | B44: Cecilia
A45: 44 | B45: Florencia Cardozzo
A46: 45 | B46: Ursula Area 11
A47: 46 | B47: Silvia
A48: 47 | B48: Iris Area 10 Lote 171
A49: 48 | B49: Lucia Area 9 Lote 229
... A56: 55 | B56: Fernando Messina Area 11

Sheet Pedidos_JA
A1: Semana | B1: Producto | C1: Costo | D1: Precio Unitario | E1: Existe Un Pedido | F1: Laura Area 10 | G1: Vale | H1: Suegra Cuñada Nori | I1: Pato | J1: Aldana Area 2 | K1: Mariana Area 7 Lote 253 | L1: Marina Moriconi | M1: Constanza Area 1 | N1: Adriana Davi A. 1 L. 222 | O1: Paola Area 10 Lote 360 | P1: Marta | Q1: Nati Conde | R1: Nati Cuñada Nori | S1: cliente | T1: cliente | U1: cliente | V1: cliente | W1: cliente | X1: cliente | Y1: cliente | Z1: cliente | AA1: cliente | AB1: TOTAL
A2: =WEEKNUM(TODAY()) -> 17 | B2: =catalog!B2 -> Nuez Mariposa Extra Light x 1 Kg | D2: =catalog!E2 -> 20500 | E2: =IF(sum(F2:AA2)>=1,"SI", "NO") -> SI | P2: 2 | AB2: =sum(F2:AA2) -> 2
A3: =WEEKNUM(TODAY()) -> 17 | B3: =catalog!B3 -> Almendra Non Pareil 27/30 x 1 Kg | D3: =catalog!E3 -> 23000 | E3: =IF(sum(F3:AA3)>=1,"SI", "NO") -> SI | J3: 1 | K3: 1 | AB3: =sum(F3:AA3) -> 2
A4: =WEEKNUM(TODAY()) -> 17 | B4: =catalog!B4 -> Mani tostado con y sin sal PREMIUM x 1 Kg | D4: =catalog!E4 -> 3000 | E4: =IF(sum(F4:AA4)>=1,"SI", "NO") -> SI | N4: 1 | P4: 1 | R4: 1 | AB4: =sum(F4:AA4) -> 3
A5: =WEEKNUM(TODAY()) -> 17 | B5: =#REF! -> #REF! | D5: =#REF! -> #REF! | E5: =IF(sum(F5:AA5)>=1,"SI", "NO") -> SI | J5: 1 | AB5: =sum(F5:AA5) -> 1
A6: =WEEKNUM(TODAY()) -> 17 | B6: =catalog!B5 -> Nuez Pecan x 1 Kg | D6: =catalog!E5 -> 34600 | E6: =IF(sum(F6:AA6)>=1,"SI", "NO") -> NO | AB6: =sum(F6:AA6) -> 0
A7: =WEEKNUM(TODAY()) -> 17 | B7: =catalog!B6 -> Cajú W4 brasilero x 1 Kg | D7: =catalog!E6 -> 19500 | E7: =IF(sum(F7:AA7)>=1,"SI", "NO") -> SI | P7: 2 | R7: 1 | AB7: =sum(F7:AA7) -> 3
A8: =WEEKNUM(TODAY()) -> 17 | B8: =catalog!B8 -> Castañas de PARA x 1 Kg | D8: =catalog!E8 -> 40200 | E8: =IF(sum(F8:AA8)>=1,"SI", "NO") -> SI | R8: 1 | AB8: =sum(F8:AA8) -> 1
A9: =WEEKNUM(TODAY()) -> 17 | B9: =catalog!B9 -> Avellanas grandes x 1 Kg | D9: =catalog!E9 -> 33200 | E9: =IF(sum(F9:AA9)>=1,"SI", "NO") -> NO | AB9: =sum(F9:AA9) -> 0
A10: =WEEKNUM(TODAY()) -> 17 | B10: =#REF! -> #REF! | D10: =#REF! -> #REF! | E10: =IF(sum(F10:AA10)>=1,"SI", "NO") -> NO | AB10: =sum(F10:AA10) -> 0
A11: =WEEKNUM(TODAY()) -> 17 | B11: =catalog!B10 -> Pasas Rubia 1kg | D11: =catalog!E10 -> 8200 | E11: =IF(sum(F11:AA11)>=1,"SI", "NO") -> NO | AB11: =sum(F11:AA11) -> 0
A12: =WEEKNUM(TODAY()) -> 17 | B12: =catalog!B11 -> Pistacho salado con cascara x 1 Kg | D12: =catalog!E11 -> 41000 | E12: =IF(sum(F12:AA12)>=1,"SI", "NO") -> NO | AB12: =sum(F12:AA12) -> 0
A13: =WEEKNUM(TODAY()) -> 17 | B13: =catalog!B13 -> Mix criollo o Runner (Nuez cuartos , almendra, cajú, mani, pasas rubias y morochas) x 1kg | D13: =catalog!E13 -> 8200 | E13: =IF(sum(F13:AA13)>=1,"SI", "NO") -> SI | H13: 1 | AB13: =sum(F13:AA13) -> 1
A14: =WEEKNUM(TODAY()) -> 17 | B14: =catalog!B15 -> Mix premium gourmet (Cajú, almendras, nueces y avellanas) x 1kg | D14: =catalog!E15 -> 23000 | E14: =IF(sum(F14:AA14)>=1,"SI", "NO") -> SI | G14: 1 | L14: 1 | P14: 3 | AB14: =sum(F14:AA14) -> 5
A15: =WEEKNUM(TODAY()) -> 17 | B15: =catalog!B17 -> Mix criollo o runner con bananitas (Cajú, almendras, nueces, mani, pasas rubias y morochas, bananitas) | D15: =catalog!E17 -> 8400 | E15: =IF(sum(F15:AA15)>=1,"SI", "NO") -> SI | I15: 1 | Q15: 1 | AB15: =sum(F15:AA15) -> 2
A16: =WEEKNUM(TODAY()) -> 17 | B16: =catalog!B18 -> Mix cervecero (semillas peladas de girasol y de zapallo, castañas de cajú saladas, maní salado, maní japonés) 1kg | D16: =catalog!E18 -> 6300 | E16: =IF(sum(F16:AA16)>=1,"SI", "NO") -> SI | H16: 1 | AB16: =sum(F16:AA16) -> 1
A17: =WEEKNUM(TODAY()) -> 17 | B17: =catalog!B21 -> Bananas disecadas x 1kg | D17: =catalog!E21 -> 12000 | E17: =IF(sum(F17:AA17)>=1,"SI", "NO") -> NO | AB17: =sum(F17:AA17) -> 0
A18: =WEEKNUM(TODAY()) -> 17 | B18: =catalog!B22 -> Damasco turco grande x 1kg | D18: =catalog!E22 -> 42000 | E18: =IF(sum(F18:AA18)>=1,"SI", "NO") -> NO | AB18: =sum(F18:AA18) -> 0
A19: =WEEKNUM(TODAY()) -> 17 | B19: =catalog!B23 -> Tomates deshidratados x 1kg | D19: =catalog!E23 -> 15600 | E19: =IF(sum(F19:AA19)>=1,"SI", "NO") -> NO | AB19: =sum(F19:AA19) -> 0
A20: =WEEKNUM(TODAY()) -> 17 | B20: =catalog!B26 -> Ciruelas d Agen sin carozo x 1kg | D20: =catalog!E26 -> 7500 | E20: =IF(sum(F20:AA20)>=1,"SI", "NO") -> SI | P20: 1 | AB20: =sum(F20:AA20) -> 1
A21: =WEEKNUM(TODAY()) -> 17 | B21: =catalog!B27 -> Arandanos | D21: =catalog!E27 -> 13500 | E21: =IF(sum(F21:AA21)>=1,"SI", "NO") -> SI | F21: 2 | P21: 1 | AB21: =sum(F21:AA21) -> 3
A22: =WEEKNUM(TODAY()) -> 17 | B22: =catalog!B28 -> Higos negros x 5kg | D22: =catalog!E28 -> 47000 | E22: =IF(sum(F22:AA22)>=1,"SI", "NO") -> NO | AB22: =sum(F22:AA22) -> 0
A23: =WEEKNUM(TODAY()) -> 17 | B23: =catalog!B29 -> Datiles Egipto Caja 1 kg OFERTA | D23: =catalog!E29 -> 8000 | E23: =IF(sum(F23:AA23)>=1,"SI", "NO") -> SI | M23: 0.5 | R23: 0.5 | AB23: =sum(F23:AA23) -> 1
A24: =WEEKNUM(TODAY()) -> 17 | B24: =#REF! -> #REF! | D24: =#REF! -> #REF! | E24: =IF(sum(F24:AA24)>=1,"SI", "NO") -> NO | AB24: =sum(F24:AA24) -> 0
A25: =WEEKNUM(TODAY()) -> 17 | B25: =catalog!B31 -> Mix de semillas (Lino, girasol, sésamo) x 1kg | D25: =catalog!E31 -> 4000 | E25: =IF(sum(F25:AA25)>=1,"SI", "NO") -> SI | I25: 1 | Q25: 1 | R25: 1 | AB25: =sum(F25:AA25) -> 3
A26: =WEEKNUM(TODAY()) -> 17 | B26: =catalog!B32 -> Lino x 1Kg | D26: =catalog!E32 -> 3300 | E26: =IF(sum(F26:AA26)>=1,"SI", "NO") -> NO | AB26: =sum(F26:AA26) -> 0
A27: =WEEKNUM(TODAY()) -> 17 | B27: =catalog!B33 -> Chia premium x 1Kg | D27: =catalog!E33 -> 8700 | E27: =IF(sum(F27:AA27)>=1,"SI", "NO") -> NO | AB27: =sum(F27:AA27) -> 0
A28: =WEEKNUM(TODAY()) -> 17 | B28: =catalog!B34 -> Sésamo integral x 1Kg | D28: =catalog!E34 -> 5800 | E28: =IF(sum(F28:AA28)>=1,"SI", "NO") -> NO | AB28: =sum(F28:AA28) -> 0
A29: =WEEKNUM(TODAY()) -> 17 | B29: =catalog!B35 -> Sesamo blanco x 1Kg | D29: =catalog!E35 -> 10000 | E29: =IF(sum(F29:AA29)>=1,"SI", "NO") -> NO | AB29: =sum(F29:AA29) -> 0
A30: =WEEKNUM(TODAY()) -> 17 | B30: =catalog!B36 -> Girasol x 1Kg | D30: =catalog!E36 -> 4100 | E30: =IF(sum(F30:AA30)>=1,"SI", "NO") -> SI | P30: 2 | AB30: =sum(F30:AA30) -> 2
A31: =WEEKNUM(TODAY()) -> 17 | B31: =catalog!B37 -> Quinoa x 1Kg | D31: =catalog!E37 -> 12400 | E31: =IF(sum(F31:AA31)>=1,"SI", "NO") -> SI | F31: 1 | AB31: =sum(F31:AA31) -> 1
A32: =WEEKNUM(TODAY()) -> 17 | B32: =catalog!B38 -> Zapallo x 1Kg | D32: =catalog!E38 -> 14000 | E32: =IF(sum(F32:AA32)>=1,"SI", "NO") -> SI | P32: 1 | AB32: =sum(F32:AA32) -> 1
A33: =WEEKNUM(TODAY()) -> 17 | B33: =catalog!B40 | D33: =catalog!E40 | E33: =IF(sum(F33:AA33)>=1,"SI", "NO") -> NO | AB33: =sum(F33:AA33) -> 0
A34: =WEEKNUM(TODAY()) -> 17 | B34: =catalog!B41 -> Harina de coco x 1Kg | D34: =catalog!E41 -> 5800 | E34: =IF(sum(F34:AA34)>=1,"SI", "NO") -> SI | F34: 2 | O34: 1 | AB34: =sum(F34:AA34) -> 3
A35: =WEEKNUM(TODAY()) -> 17 | B35: =catalog!B43 -> Harina de almendras con piel- OFERTA x 1Kg | D35: =catalog!E43 -> 4300 | E35: =IF(sum(F35:AA35)>=1,"SI", "NO") -> SI | H35: 1 | AB35: =sum(F35:AA35) -> 1
A36: =WEEKNUM(TODAY()) -> 17 | B36: =catalog!B44 -> Harina de almendras sin piel- OFERTA x 1Kg | D36: =catalog!E44 -> 4600 | E36: =IF(sum(F36:AA36)>=1,"SI", "NO") -> SI | O36: 2 | Q36: 1 | AB36: =sum(F36:AA36) -> 3
A37: =WEEKNUM(TODAY()) -> 17 | B37: =catalog!B45 | D37: =catalog!E45 | E37: =IF(sum(F37:AA37)>=1,"SI", "NO") -> NO | AB37: =sum(F37:AA37) -> 0
A38: =WEEKNUM(TODAY()) -> 17 | B38: =catalog!B46 | D38: =catalog!E46 | E38: =IF(sum(F38:AA38)>=1,"SI", "NO") -> NO | AB38: =sum(F38:AA38) -> 0
A39: =WEEKNUM(TODAY()) -> 17 | B39: =catalog!B47 -> Fécula de mandioca x 5Kg | D39: =catalog!E47 -> 11000 | E39: =IF(sum(F39:AA39)>=1,"SI", "NO") -> NO | AB39: =sum(F39:AA39) -> 0
A40: =WEEKNUM(TODAY()) -> 17 | B40: =catalog!B48 -> Harina de arroz x 5Kg | D40: =catalog!E48 -> 7500 | E40: =IF(sum(F40:AA40)>=1,"SI", "NO") -> NO | AB40: =sum(F40:AA40) -> 0
...

Sheet PEDIDOS m y m
C1: Cliente | D1: Producto | E1: Cantidad | F1: Precio Unitario | G1: Total | I1: Notas (lugar)
A2: 45730 | C2: Cecilia (Lauti) | D2: Mix Premiun gourmet | E2: 1kg | F2: 17480 | G2: 17480 | I2: Area 10 Lote 268 SS | J2: pago
A3: 45730 | C3: Cecilia (Lauti) | D3: Quinoa | E3: 1kg | F3: 6900 | G3: 6900 | I3: Area 10 Lote 268 SS | J3: pago
A4: 15/3/25 | C4: Marianela (Laure) | D4: Mani Tostado sin sal | E4: 1kg | F4: 3000 | G4: 3000 | I4: Area 6 Lote 233 SS | J4: pago
A5: 15/3/25 | C5: Marianela (Laure) | D5: Mix Criollo o runner con banan | E5: 1kg | F5: 6500 | G5: 6500 | I5: Area 6 Lote 234 SS | J5: pago
A6: 17/3/25 | C6: Marcela Rivera | D6: Mix Criollo o runner con banan | E6: 1kg | F6: 6500 | G6: 6500 | I6: Area 2 Lote 6 SS | J6: Pago
A7: 17/3/25 | C7: Marcela Rivera | D7: Harina de Almendras sin piel | E7: 2 kg | F7: 4200 | G7: 4200 | H7: Separadas1kg y 1kg | I7: Area 2 Lote 6 SS | J7: Pago
A8: 17/3/25 | C8: Marcela Rivera | D8: Mermelada Los Carolinos Durazno | E8: 1 | F8: 4200 | G8: 3000 | I8: Area 2 Lote 6 SS | J8: Pago
A9: 17/3/25 | C9: Marcela Rivera | D9: Nuez Mariposa | E9: 1kg | F9: 20600 | G9: 20600 | I9: Area 2 Lote 6 SS | J9: Pago
A10: 17/3/25 | C10: Marcela Rivera | D10: Mani Tostado con sal | E10: 1kg | F10: 3000 | G10: 3000 | I10: Area 2 Lote 6 SS | J10: Pago
A11: 45734 | C11: Rosario | D11: Mix Premium gourmet (cajú, alm | E11: 1kg | F11: 18000 | G11: 18000 | I11: Area 1 Lote 479 | J11: Pago
A12: 45734 | C12: Rosario | D12: Pistachos con cascara | E12: 1kg | F12: 33000 | G12: 33000 | I12: Area 1 Lote 479 | J12: Pago
A13: 45734 | C13: Rosario | D13: Harina de Almendras con piel | E13: 1kg | F13: 4000 | G13: 4000 | I13: Area 1 Lote 479 | J13: Pago
C14: Marina yo | D14: Mani con sal | E14: 1kg | F14: 3000
C15: Marina yo | D15: Pistachos con cascara | E15: 1gr | F15: 33000
C16: Marina yo | D16: Mix Premium gourmet (cajú, alm | E16: 1kg | F16: 15500
C17: Marina yo | D17: Bananas disecadas | E17: 1kg | F17: 6400
C18: Marina yo | D18: Harina de coco | E18: 2kg | F18: 9200
C19: Marina yo | D19: Harina de Almendras | E19: 1kg | F19: 3400
C20: Marina yo | D20: Fecula de Mandioca | E20: 1kg
C21: Marina yo | D21: Aceite de coco neutro x 360 | E21: 1 unidad | F21: 3300
C22: Marina yo | D22: Chip chocolate | E22: 1gr | F22: 6600
C23: Marina yo | D23: Galletitas Nutresan sabor coco | E23: 1 una | F23: 1130
C24: Marina yo | D24: Galletitas Nutresan sabor algarroba | E24: 1 una | F24: 1140
C25: Saha | D25: Mix Premium gourmet (cajú, alm | E25: 1 kg | F25: 18000 | I25: pago
C26: Raul | D26: mani con sal | E26: 1 kg | F26: 3000 | I26: pago
D27: castañas caju | E27: 1 kg | F27: 12500
D28: arandanos | E28: 1 kg | F28: 10500
D29: mix semillas | E29: 1 kg | F29: 3000
D30: pasas con chocolate | E30: 1 kg | F30: 13200
C31: Gustavo | D31: Mix Premium gourmet (cajú, alm | E31: 2 kg | F31: 36000 | I31: pagó
C32: Gabi | D32: arandanos | E32: 2 kg | F32: 21000 | I32: pago
D33: castañas para | E33: 1 kg | F33: 19400
C34: Luciano | D34: arandanos | E34: 1 kg | F34: 10500 | I34: pagó
C35: yo | D35: nueces pecan | E35: 1 kg | F35: 17100
F36: =sum(F2:F35) -> 374250
A38: 45743
C39: Auri | D39: mix criollo con bananitas | E39: 1 | F39: 6700 | H39: 6000 | I39: pago
D40: mix criollo con bananitas | E40: 1 | F40: 6900 | H40: 6000
D41: mermelada naranja | E41: 1 | F41: 3000 | H41: 2200
...

Sheet Hoja 7
